name: Issue on PR Rollback
on:
  pull_request:
    types: [opened, synchronize, reopened, closed]
    branches: [main]
env:
  PYTHON_VERSION: "3.9"
jobs:
  test-and-rollback:
    runs-on: ubuntu-latest
    steps:
      - uses: actions/checkout@v4
        with:
          fetch-depth: 0 # Full history for rollback
      - name: Set up Python
        uses: actions/setup-python@v5
        with:
          python-version: ${{ env.PYTHON_VERSION }}
      - name: Cache Dependencies
        uses: actions/cache@v3
        with:
          path: ~/.cache/pip
          key: ${{ runner.os }}-pip-${{ hashFiles('requirements.txt') }}
      - name: Install Dependencies
        run: |
          python -m pip install --upgrade pip
          pip install -r requirements.txt pytest
      - name: Run ML Tests
        run: |
          python -m pytest tests/ --cov=./ --cov-report=xml
      - name: Upload Coverage
        uses: codecov/codecov-action@v3
        with:
          token: ${{ secrets.CODECOV_TOKEN }}
      - name: Rollback on Failure
        if: failure() && github.event.action != 'closed'
        run: |
          git revert HEAD -n
          git commit -m "Revert PR #${{ github.event.pull_request.number }} due to test failure"
          git push origin ${{ github.head_ref }}
        env:
          GITHUB_TOKEN: ${{ secrets.GITHUB_TOKEN }}
      - name: Create Issue on Failure
        if: failure()
        uses: actions/github-script@v6
        with:
          github-token: ${{ secrets.GITHUB_TOKEN }}
          script: |
            github.rest.issues.create({
              owner: context.repo.owner,
              repo: context.repo.repo,
              title: `PR #${{ github.event.pull_request.number }} Failed - Rollback Initiated`,
              body: `Tests failed on PR #${{ github.event.pull_request.number }}. Rolled back changes. See logs for details.`
            })
